<?xml version="1.0"?>
<robot xmlns:xacro="http://www.ros.org/wiki/xacro">
  <xacro:include filename="$(find ram_support)/urdf/xacros/implant_grasp_fingers.xacro"/>
  <xacro:property name="max_effort" value="300"/> <!-- Should be changed to match the robots specs -->
  
  <xacro:macro name="schunk_gripper" params="hardware_interface robot_name">
    
    <link name="${robot_name}_link_main_body">
      
      <visual>
        <origin xyz="0 0 0" rpy="0 0 0"/>
        <geometry>
          <mesh filename="package://ram_support/meshes/schunk_gripper/pgn_100/visual/main_body.dae"/>
        </geometry>
      </visual>
      
      <collision>
        <origin xyz="0 0 0" rpy="0 0 0"/>
        <geometry>
          <mesh filename="package://ram_support/meshes/schunk_gripper/pgn_100/collision/main_body.stl" scale="0.001 0.001 0.001"/>
        </geometry>
      </collision>
    </link>
    
    <!-- joint between main body and left jaw -->
    <joint name="${robot_name}_joint_left" type="prismatic">
      <parent link="${robot_name}_link_main_body"/>
      <child link="${robot_name}_link_left"/>
      <origin xyz="-0.0058 0 0.0341" rpy="${pi/2} 0 -${pi/2}"/>
      <axis xyz="0 0 -1"/>
      <limit lower="0.0008" upper="0.0058"
             effort="${max_effort}" velocity="0.0833" />
    </joint>
    
    <link name="${robot_name}_link_left">
      <visual>
        <origin xyz="0 0 0" rpy="0 0 0"/>
        <geometry>
          <mesh filename="package://ram_support/meshes/schunk_gripper/pgn_100/visual/left_gripper.dae"/>
        </geometry>
      </visual>
      
      <collision>
        <origin xyz="0 0 0" rpy="0 0 0"/>
        <geometry>
          <mesh filename="package://ram_support/meshes/schunk_gripper/pgn_100/collision/left_gripper.stl" scale="0.001 0.001 0.001"/>
        </geometry>
      </collision>
    </link>
    
   <!-- joint between main body and right jaw -->
    <joint name="${robot_name}_joint_right" type="prismatic">
      <parent link="${robot_name}_link_main_body"/>
      <child link="${robot_name}_link_right"/>
      <origin xyz="0.0058 0 0.0341" rpy="${pi/2} 0 ${pi/2}"/>
      <axis xyz="0 0 -1"/>
      <limit lower="0.0008" upper="0.0058"
             effort="${max_effort}" velocity="0.0833" />
      <mimic joint="${robot_name}_joint_left"/>
    </joint>
    
    <link name="${robot_name}_link_right">
      <visual>
        <origin xyz="0 0 0" rpy="0 0 0"/>
        <geometry>
          <mesh filename="package://ram_support/meshes/schunk_gripper/pgn_100/visual/right_gripper.dae"/>
        </geometry>
      </visual>
      
      <collision>
        <origin xyz="0 0 0" rpy="0 0 0"/>
        <geometry>
          <mesh filename="package://ram_support/meshes/schunk_gripper/pgn_100/collision/right_gripper.stl" scale="0.001 0.001 0.001"/>
        </geometry>
      </collision>
    </link>
    
    <transmission name="${robot_name}_tran_right">
      <type>transmission_interface/SimpleTransmission</type>
      <joint name="${robot_name}_joint_right">
	<hardwareInterface>hardware_interface/${hardware_interface}</hardwareInterface>
      </joint>
      <actuator name="${robot_name}_motor_right">
	<hardwareInterface>hardware_interface/${hardware_interface}</hardwareInterface>
	<mechanicalReduction>1</mechanicalReduction>
      </actuator>
    </transmission>

    <transmission name="${robot_name}_tran_left">
      <type>transmission_interface/SimpleTransmission</type>
      <joint name="${robot_name}_joint_left">
	<hardwareInterface>hardware_interface/${hardware_interface}</hardwareInterface>
      </joint>
      <actuator name="${robot_name}_motor_left">
	<hardwareInterface>hardware_interface/${hardware_interface}</hardwareInterface>
	<mechanicalReduction>1</mechanicalReduction>
      </actuator>
    </transmission>

    <xacro:implant_grasp_fingers gripper_name="$(arg gripper_name)"/>

  </xacro:macro>
  
</robot>